Workbook

Sheet Raw_Data
A1: ref_number | B1: disclosure_group | C1: title_en | D1: title_fr | E1: name | F1: purpose_en | G1: purpose_fr | H1: start_date | I1: end_date | J1: destination_en | K1: destination_fr | L1: destination_2_en | M1: destination_2_fr | N1: destination_other_en | O1: destination_other_fr | P1: airfare | Q1: other_transport | R1: lodging | S1: meals | T1: other_expenses | U1: total | V1: additional_comments_en | W1: additional_comments_fr | X1: owner_org | Y1: owner_org_title
A2: T-20120-P11-001 | B2: SLE | C2: Chief Executive Officer | D2: Président directeur-général | E2: Philip Rizcallah | F2: To attend meeting with Saskatchewan Provincial Government | G2: Pour assister à une réunion avec le gouvernement provincial de la Saskatchewan | H2: 43864 | I2: 43865 | J2: Regina, Saskatchewan, Canada | K2: Regina, Saskatchewan, Canada | P2: 646.17 | Q2: 117.26 | R2: 157.78 | S2: 197.25 | T2: 0 | U2: 1118.46 | X2: casdo-ocena | Y2: Accessibility Standards Canada | Normes d’accessibilité Canada
A3: T-2020-P11-0001 | B3: SLE | C3: Chair | D3: Président | E3: Bérubé, Paul-Claude | F3: Board members meeting | G3: Réunion du conseil | H3: 43870 | I3: 43874 | J3: Vancouver, British Columbia, Canada | K3: Vancouver, Colombie-Britannique | P3: 1104.27 | Q3: 189.72 | R3: 841.31 | S3: 461.84 | U3: 2597.14 | X3: casdo-ocena | Y3: Accessibility Standards Canada | Normes d’accessibilité Canada
A4: T-2020-P11-0002 | B4: SLE | C4: Vice Chair | D4: vice-présidente | E4: Reid, Mary | F4: Board members meeting | G4: Réunion du conseil | H4: 43870 | I4: 43875 | J4: Vancouver, British Columbia, Canada | K4: Vancouver, Colombie-Britannique | P4: 2511.31 | Q4: 132.48 | R4: 785.65 | S4: 591 | T4: 108.3 | U4: 4128.74 | X4: casdo-ocena | Y4: Accessibility Standards Canada | Normes d’accessibilité Canada
A5: T-2020-P11-0003 | B5: SLE | C5: Board Of Directors | D5: Membre du conseil de direction | E5: McLaughlin, Joseph | F5: Board members meeting | G5: Réunion du conseil | H5: 43870 | I5: 43873 | J5: Vancouver, British Columbia, Canada | K5: Vancouver, Colombie-Britannique | Q5: 58.32 | R5: 630.99 | S5: 264.6 | T5: 123 | U5: 1076.91 | X5: casdo-ocena | Y5: Accessibility Standards Canada | Normes d’accessibilité Canada
A6: T-2020-P11-0004 | B6: SLE | C6: Board Of Directors | D6: Membre du conseil de direction | E6: Haan, Maureen | F6: Board members meeting | G6: Réunion du conseil | H6: 43870 | I6: 43873 | J6: Vancouver, British Columbia, Canada | K6: Vancouver, Colombie-Britannique | P6: 880.99 | Q6: 192.76 | R6: 630.99 | S6: 332.45 | U6: 2037.19 | X6: casdo-ocena | Y6: Accessibility Standards Canada | Normes d’accessibilité Canada
A7: T-2020-P11-0005 | B7: SLE | C7: Board Of Directors | D7: Membre du conseil de direction | E7: Hartin, Penny | F7: Board members meeting | G7: Réunion du conseil | H7: 43870 | I7: 43873 | J7: Vancouver, British Columbia, Canada | K7: Vancouver, Colombie-Britannique | P7: 935.23 | Q7: 117.3 | R7: 630.99 | S7: 353.05 | U7: 2036.57 | X7: casdo-ocena | Y7: Accessibility Standards Canada | Normes d’accessibilité Canada
A8: T-2020-P11-0006 | B8: SLE | C8: Board Of Directors | D8: Membre du conseil de direction | E8: Earle, Kory | F8: Board members meeting | G8: Réunion du conseil | H8: 43870 | I8: 43873 | J8: Vancouver, British Columbia, Canada | K8: Vancouver, Colombie-Britannique | P8: 949.11 | R8: 630.99 | S8: 373.4 | U8: 1953.5 | X8: casdo-ocena | Y8: Accessibility Standards Canada | Normes d’accessibilité Canada
A9: T-2020-P11-0007 | B9: SLE | C9: Board Of Directors | D9: Membre du conseil de direction | E9: Ringaert, Laurie | F9: Board members meeting | G9: Réunion du conseil | H9: 43870 | I9: 43873 | J9: Vancouver, British Columbia, Canada | K9: Vancouver, Colombie-Britannique | P9: 662.91 | Q9: 128.43 | R9: 630.99 | S9: 332.45 | U9: 1754.78 | X9: casdo-ocena | Y9: Accessibility Standards Canada | Normes d’accessibilité Canada
A10: T-2020-P11-0008 | B10: SLE | C10: Board Of Directors | D10: Membre du conseil de direction | E10: Khedr, Rabia | F10: Board members meeting | G10: Réunion du conseil | H10: 43870 | I10: 43873 | J10: Vancouver, British Columbia, Canada | K10: Vancouver, Colombie-Britannique | P10: 935.23 | Q10: 118.3 | R10: 630.99 | S10: 353.05 | U10: 2037.57 | X10: casdo-ocena | Y10: Accessibility Standards Canada | Normes d’accessibilité Canada
A11: T-2020-P11-0009 | B11: SLE | C11: Chief Executive Officer | D11: Président-directeur général | E11: Rizcallah, Philip | F11: Board members meeting | G11: Réunion du conseil | H11: 43870 | I11: 43875 | J11: Vancouver, British Columbia, Canada | K11: Vancouver, Colombie-Britannique | P11: 1313.32 | Q11: 342.77 | R11: 970.75 | S11: 591 | T11: 313 | U11: 3530.84 | X11: casdo-ocena | Y11: Accessibility Standards Canada | Normes d’accessibilité Canada
A12: T-2020-P1-0001 | B12: SLE | C12: Chair | D12: Président | E12: Bérubé, Paul-Claude | F12: Meeting with Chief Executive Officer of Accessibility Stadards Canada | G12: Réunion avec le Président-directeur général de Normes d’accessibilité Canada | H12: 43880 | I12: 43880 | J12: Montreal, Quebec, Canada | K12: Montréal, Québec, Canada | Q12: 62.06 | R12: 0 | S12: 20.6 | U12: 82.66 | X12: casdo-ocena | Y12: Accessibility Standards Canada | Normes d’accessibilité Canada
A13: T-2020-P1-0002 | B13: SLE | C13: Chair | D13: Président | E13: Bérubé, Paul-Claude | F13: Meeting with Chief Executive Officer and Staff of of Accessibility Stadards Canada | G13: Réunion avec le Président-directeur général et employés de Normes d’accessibilité Canada | H13: 43885 | I13: 43885 | J13: Ottawa, Ontario, Canada | K13: Ottawa, Ontario, Canada | Q13: 276.06 | R13: 0 | S13: 91.5 | U13: 367.56 | X13: casdo-ocena | Y13: Accessibility Standards Canada | Normes d’accessibilité Canada
A14: T-2020-P1-0003 | B14: SLE | C14: Chief Executive Officer | D14: Président-directeur général | E14: Rizcallah, Philip | F14: Meetings with various Stakeholders | G14: Réunions avec divers intervenants | H14: 43851 | I14: 43855 | J14: Toronto, Ontario and Halifax, Nova Scotia, Canada | K14: Toronto, Ontario et Halifax, Nouvelle-Écosse, Canada | P14: 1190.86 | Q14: 359.36 | R14: 344.73 | S14: 394.25 | T14: 172.2 | U14: 2461.4 | X14: casdo-ocena | Y14: Accessibility Standards Canada | Normes d’accessibilité Canada
A15: T-2020-P2-0001 | B15: SLE | C15: Chief Executive Officer | D15: Président-directeur général | E15: Rizcallah, Philip | F15: To attend Canadian Accessibility Standards Development Organization business meetings | G15: Pour assister des réunions d'affaire de l'Organisation Canadienne d'élaboration de normes d'accessibilité | H15: 43900 | I15: 43900 | J15: Montréal, Quebec, Canada | K15: Montréal, Québec, Canada | P15: 0 | Q15: 339.57 | R15: 0 | S15: 71.15 | T15: 3.2 | U15: 413.92 | X15: casdo-ocena | Y15: Accessibility Standards Canada | Normes d’accessibilité Canada
A16: T-2020-P2-0002 | B16: SLE | C16: Chief Executive Officer | D16: Président-directeur général | E16: Rizcallah, Philip | F16: To attend meeting with Chair and Chief Operating Officer | G16: Pour assister à une réunion avec le Président et le Chef de l’exploitation | H16: 43880 | I16: 43880 | J16: Montréal, Quebec, Canada | K16: Montréal, Québec, Canada | P16: 0 | Q16: 267.25 | R16: 0 | S16: 20.6 | T16: 0 | U16: 287.85 | X16: casdo-ocena | Y16: Accessibility Standards Canada | Normes d’accessibilité Canada
A17: T-2020-P2-0003 | B17: SLE | C17: Chief Executive Officer | D17: Président-directeur général | E17: Rizcallah, Philip | F17: To attend meeting with Chair | G17: Pour assister à une réunion avec le Président | H17: 43867 | I17: 43868 | J17: Saint-Jean-sur-Richelieu, Quebec, Canada | K17: Saint-Jean-sur-Richelieu, Québec, Canada | P17: 0 | Q17: 315.28 | R17: 0 | S17: 91.5 | T17: 3.2 | U17: 409.98 | X17: casdo-ocena | Y17: Accessibility Standards Canada | Normes d’accessibilité Canada
A18: T-2020-P2-0004 | B18: SLE | C18: Chair | D18: Président | E18: Bérubé, Paul-Claude | F18: To attend meeting with Canadian Accessibility Standards Development Organization Chief Executive Officer and Vice-chair | G18: Pour assister à une réunion avec le Directeur général et le Vice-Président du Conseil d'administration de l'Organisation Canadienne d'élaboration de normes d'accessibilité | H18: 43858 | I18: 43858 | J18: Ottawa, Ontario, Canada | K18: Ottawa, Ontario, Canada | P18: 0 | Q18: 563.09 | R18: 0 | S18: 20.6 | T18: 0 | U18: 583.69 | X18: casdo-ocena | Y18: Accessibility Standards Canada | Normes d’accessibilité Canada
A19: T-2020-P2-0005 | B19: SLE | C19: Chair | D19: Président | E19: Bérubé, Paul-Claude | F19: Physical presence required for Canadian Accessibility Standards Development Organization board members meeting | G19: Participer à la réunion du conseil d'administration de l'Organisation canadienne d'élaboration de normes d'accessibilité | H19: 43851 | I19: 43851 | J19: Ottawa, Ontario, Canada | K19: Ottawa, Ontario, Canada | P19: 0 | Q19: 440.71 | R19: 0 | S19: 20.6 | T19: 0 | U19: 461.31 | X19: casdo-ocena | Y19: Accessibility Standards Canada | Normes d’accessibilité Canada
A20: T-2020-P2-0006 | B20: SLE | C20: Vice Chair | D20: Vice-Présidente | E20: Reid, Mary | F20: To attend meeting with Canadian Accessibility Standards Development Organization Chief Executive Officer and Chair | G20: Pour assister à une réunion avec le Directeur général du Conseil d'administration et le président de l'Organisation Canadienne d'élaboration de normes d'accessibilité | H20: 43899 | I20: 43900 | J20: Montréal, Quebec, Canada | K20: Montréal, Québec, Canada | P20: 1278.66 | Q20: 32 | R20: 50 | S20: 112.1 | T20: 0 | U20: 1472.76 | X20: casdo-ocena | Y20: Accessibility Standards Canada | Normes d’accessibilité Canada
A21: T-2020-P2-0007 | B21: SLE | C21: Vice Chair | D21: Vice-Présidente | E21: Reid, Mary | F21: To attend meeting with Canadian Accessibility Standards Development Organization Chief Executive Officer | G21: Pour assister à une réunion avec le Directeur général du Conseil d'administration de l'Organisation Canadienne d'élaboration de normes d'accessibilité | H21: 43849 | I21: 43850 | J21: Ottawa, Ontario, Canada | K21: Ottawa, Ontario, Canada | P21: 1210.74 | Q21: 70.25 | R21: 269.12 | S21: 197.25 | T21: 0 | U21: 1747.36 | X21: casdo-ocena | Y21: Accessibility Standards Canada | Normes d’accessibilité Canada
A22: T-2020-P2-0008 | B22: SLE | C22: Board Of Directors | D22: Membre du conseil d'administration | E22: Adair, William | F22: Physical presence required for Canadian Accessibility Standards Development Organization board members meeting | G22: Participer à la réunion du conseil d'administration de l'Organisation canadienne d'élaboration de normes d'accessibilité | H22: 43870 | I22: 43873 | J22: Vancouver, British Columbia, Canada | K22: Vancouver, Colombie-Britannique, Canada | P22: 894.55 | Q22: 163.15 | R22: 630.99 | S22: 353.05 | T22: 0 | U22: 2041.74 | X22: casdo-ocena | Y22: Accessibility Standards Canada | Normes d’accessibilité Canada
A23: T-2022-P5-0001 | B23: SLE | C23: Chief Executive Officer | D23: Président-directeur général | E23: Rizcallah, Philip | F23: Meeting with Government of Quebec | G23: Réunion avec le gouvernement du Québec | H23: 44518 | I23: 44519 | J23: Brossard, Quebec, Canada | K23: Brossard, Québec, Canada | P23: 0 | Q23: 324.3 | R23: 177.31 | S23: 183.55 | T23: 11.6 | U23: 696.76 | X23: casdo-ocena | Y23: Accessibility Standards Canada | Normes d’accessibilité Canada
A24: T-2022-P5-0002 | B24: SLE | C24: Chief Executive Officer | D24: Président-directeur général | E24: Rizcallah, Philip | F24: Meeting with the Office des personnes handicapées du Québec | G24: Réunion avec l'Office des personnes handicapées du Québec | H24: 44545 | I24: 44546 | J24: Québec, Quebec, Canada | K24: Québec, Québec, Canada | P24: 811.86 | Q24: 235.12 | R24: 154.7 | S24: 226.5 | T24: 0 | U24: 1428.18 | X24: casdo-ocena | Y24: Accessibility Standards Canada | Normes d’accessibilité Canada
A25: T-2022-P5-0004 | B25: SLE | C25: Chief Executive Officer | D25: Président-directeur général | E25: Rizcallah, Philip | F25: Stakeholder meetings in Atlantic Canada | G25: Réunions avec parties prenantes | H25: 44604 | I25: 44615 | J25: St. John's, NL | K25: St. John's, TN | P25: 1095.53 | Q25: 304.61 | R25: 553.43 | S25: 884.65 | T25: 253.04 | U25: 3091.26 | X25: casdo-ocena | Y25: Accessibility Standards Canada | Normes d’accessibilité Canada
A26: T-2022-P5-0005 | B26: SLE | C26: Chief Executive Officer | D26: Président-directeur général | E26: Rizcallah, Philip | F26: Meeting with Legislative Assembly of New Brunswick | G26: Réunion avec l'Assemblée législative due Nouveau-Brunswick | H26: 44620 | I26: 44621 | J26: Fredericton, NB | K26: Fredericton, NB | P26: 817.28 | Q26: 237.17 | R26: 151.17 | S26: 205.15 | T26: 0 | U26: 1410.77 | X26: casdo-ocena | Y26: Accessibility Standards Canada | Normes d’accessibilité Canada
A27: T-2023-P2-0001 | B27: SLE | C27: Chief Executive Officer | D27: Président-directeur général | E27: Rizcallah, Philip | F27: Stakeholder meetings in Toronto | G27: Réunions avec des parties prenantes à Toronto | H27: 44658 | I27: 44660 | J27: Toronto, Ontario, Canada | K27: Toronto, Ontario, Canada | P27: 721.22 | Q27: 193.16 | R27: 491.24 | S27: 292.85 | U27: 1698.47 | X27: casdo-ocena | Y27: Accessibility Standards Canada | Normes d’accessibilité Canada
A28: T-2023-P3-0001 | B28: SLE | C28: Chief Executive Officer | D28: Président-directeur général | E28: Rizcallah, Philip | F28: Stakeholder meetings in Halifax | G28: Réunions avec des parties prenantes à Halifax | H28: 44663 | I28: 44668 | J28: Halifax, Nova Scotia, Canada | K28: Halifax, Nouvelle-Ecosse, Canada | P28: 651.37 | Q28: 279.34 | R28: 594.72 | S28: 342.4 | T28: 14.27 | U28: 1882.1 | X28: casdo-ocena | Y28: Accessibility Standards Canada | Normes d’accessibilité Canada
A29: T-2023-P3-0002 | B29: SLE | C29: Chief Executive Officer | D29: Président-directeur général | E29: Rizcallah, Philip | F29: Stakeholder meetings in Edmonton | G29: Réunions avec des parties prenantes en Edmonton | H29: 44677 | I29: 44679 | J29: Edmonton, Alberta | K29: Edmonton, Alberta | P29: 1504.7 | Q29: 205.31 | R29: 334.56 | S29: 347.25 | T29: 0 | U29: 2391.82 | X29: casdo-ocena | Y29: Accessibility Standards Canada | Normes d’accessibilité Canada
A30: T-2023-P3-0003 | B30: SLE | C30: Chief Executive Officer | D30: Président-directeur général | E30: Rizcallah, Philip | F30: Stakeholder meetings in Victoria and Vancouver | G30: Réunions avec des parties prenantes à Victoria et Vancouver | H30: 44704 | I30: 44707 | J30: Victoria and Vancouver, British Columbia, Canada | K30: Victoria et Vancouver, Colombie-Britannique | P30: 1818.5 | Q30: 691.09 | R30: 900.59 | S30: 463 | T30: 0 | U30: 3873.18 | X30: casdo-ocena | Y30: Accessibility Standards Canada | Normes d’accessibilité Canada
A31: T-2023-P4-0001 | B31: SLE | C31: Chief Executive Officer | D31: Président-directeur général | E31: Rizcallah, Philip | F31: Stakeholder meetings in Moncton | G31: Réunions avec des parties prenantes à Moncton | H31: 44733 | I31: 44734 | J31: Moncton, New Brunswick, Canada | K31: Moncton, Nouveau Brunswick, Canada | P31: 986.9 | Q31: 182.9 | R31: 141.55 | S31: 231.5 | T31: 0 | U31: 1542.85 | X31: casdo-ocena | Y31: Accessibility Standards Canada | Normes d’accessibilité Canada
A32: T-2023-P4-0002 | B32: SLE | C32: Chief Executive Officer | D32: Président-directeur général | E32: Rizcallah, Philip | F32: Stakeholder meetings in Toronto | G32: Réunions avec des parties prenantes en Toronto | H32: 44735 | I32: 44736 | J32: Toronto, Ontario, Canada | K32: Toronto, Ontario, Canada | P32: 0 | Q32: 665.2 | R32: 404.27 | S32: 231.5 | T32: 23.73 | U32: 1324.7 | X32: casdo-ocena | Y32: Accessibility Standards Canada | Normes d’accessibilité Canada
A33: T-2023-P5-0001 | B33: SLE | C33: Chief Executive Officer | D33: Président-directeur général | E33: Rizcallah, Philip | F33: CACP CIPH Annual Meeting | G33: Réunion annuelle CACP CIPH | H33: 44787 | I33: 44790 | J33: Halifax, Nova Scotia, Canada | K33: Halifax, Nouvelle Ecosse, Canada | P33: 698.64 | Q33: 278.92 | R33: 443.4 | S33: 468.95 | T33: 0 | U33: 1889.91 | X33: casdo-ocena | Y33: Accessibility Standards Canada | Normes d’accessibilité Canada
A34: T-2023-P5-0002 | B34: SLE | C34: Chief Executive Officer | D34: Président-directeur général | E34: Rizcallah, Philip | F34: Standard and training review | G34: Formation des normes | H34: 44798 | I34: 44800 | J34: Peterborough, Ontario, Canada | K34: Peterborough, Ontario, Canada | P34: 0 | Q34: 336.6 | R34: 369.75 | S34: 270.95 | T34: 0 | U34: 977.3 | X34: casdo-ocena | Y34: Accessibility Standards Canada | Normes d’accessibilité Canada
A35: T-2023-P5-0003 | B35: SLE | C35: Chair | D35: Président | E35: Bérubé, Paul-Claude | F35: Meeting with CEO | G35: Réunion avec PDG | H35: 44769 | I35: 44769 | J35: Brossard, Quebec, Canada | K35: Brossard, Québec, Canada | P35: 0 | Q35: 41.25 | R35: 0 | S35: 22.15 | T35: 0 | U35: 63.4 | X35: casdo-ocena | Y35: Accessibility Standards Canada | Normes d’accessibilité Canada
A36: T-2023-P5-0004 | B36: SLE | C36: Chair | D36: Président | E36: Bérubé, Paul-Claude | F36: Meeting with Vie Autonome | G36: Réunion avec Vie Autonome | H36: 44779 | I36: 44779 | J36: Val d'Or, Quebec, Canada | K36: Val d'Or, Québec, Canada | P36: 1633.64 | Q36: 108.7 | R36: 0 | S36: 98.45 | T36: 0 | U36: 1840.79 | X36: casdo-ocena | Y36: Accessibility Standards Canada | Normes d’accessibilité Canada
A37: T-2023-P5-0005 | B37: SLE | C37: Chair | D37: Président | E37: Bérubé, Paul-Claude | F37: Meeting with CEO and co-Chair | G37: Réunion avec PDG et co-président | H37: 44752 | I37: 44754 | J37: Gatineau, Quebec, Canada | K37: Gatineau, Québec, Canada | P37: 0 | Q37: 296.04 | R37: 783.04 | S37: 259.4 | T37: 0 | U37: 1338.48 | X37: casdo-ocena | Y37: Accessibility Standards Canada | Normes d’accessibilité Canada
A38: T-2023-P5-0006 | B38: SLE | C38: Board Member | D38: Membre du conseil d'administration | E38: McLaughlin, Joseph | F38: Stakeholder meeting | G38: Réunion des parties prenantes | H38: 44706 | I38: 44706 | J38: Vancouver, British Columbia, Canada | K38: Vancouver, Colombie Britannique, Canada | P38: 0 | Q38: 49.68 | R38: 0 | S38: 0 | U38: 49.68 | X38: casdo-ocena | Y38: Accessibility Standards Canada | Normes d’accessibilité Canada
A39: T-2023-P6-0001 | B39: SLE | C39: Vice Chair | D39: Vice président | E39: Reid, Mary | F39: Meeting with CEO and Chair | G39: Réunion avec PDG et Président | H39: 44745 | I39: 44755 | J39: Gatineau, Quebec, Canada | K39: Gatineau, Québec, Canada | P39: 780.54 | Q39: 50 | R39: 371.32 | S39: 270.7 | T39: 0 | U39: 1472.56 | X39: casdo-ocena | Y39: Accessibility Standards Canada | Normes d’accessibilité Canada
A40: T-2023-P7-0001 | B40: SLE | C40: Chief Executive Officer | D40: Président-directeur général | E40: Rizcallah, Philip | F40: International conference on Universal Design | G40: Conférence internationale sur la conception universelle | H40: 44805 | I40: 44814 | J40: Venice, Italy | K40: Venise, Italie | P40: 12175.56 | Q40: 592.46 | R40: 996.34 | S40: 731.55 | T40: 0 | U40: 14495.91 | X40: casdo-ocena | Y40: Accessibility Standards Canada | Normes d’accessibilité Canada
...

Sheet Cleaned_Data
A1: ref_number | B1: disclosure_group | C1: title_en | D1: title_fr | E1: name | F1: purpose_en | G1: purpose_fr | H1: start_date | I1: end_date | J1: destination_en | K1: destination_fr | L1: destination_2_en | M1: destination_2_fr | N1: destination_other_en | O1: destination_other_fr | P1: airfare | Q1: other_transport | R1: lodging | S1: meals | T1: other_expenses | U1: total | V1: additional_comments_en | W1: additional_comments_fr | X1: owner_org | Y1: owner_org_title | Z1: Travel_Days | AA1: Calculated_Total | AB1: Total_Difference | AC1: Duplicate_Flag | AD1: Data_Quality_Status | AE1: Total_Check
A2: T-20120-P11-001 | B2: SLE | C2: Chief Executive Officer | D2: Président directeur-général | E2: Philip Rizcallah | F2: To attend meeting with Saskatchewan Provincial Government | G2: Pour assister à une réunion avec le gouvernement provincial de la Saskatchewan | H2: 43864 | I2: 43865 | J2: Regina, Saskatchewan, Canada | K2: Regina, Saskatchewan, Canada | P2: 646.17 | Q2: 117.26 | R2: 157.78 | S2: 197.25 | T2: 0 | U2: 1118.46 | X2: casdo-ocena | Y2: Accessibility Standards Canada | Normes d’accessibilité Canada | Z2: 2 | AA2: 1118.46 | AB2: =ROUND(U2-AA2,2) | AC2: FALSE | AD2: =IF(U2="","MISSING_TOTAL",IF(ABS(AB2)<=0.01,"OK","CHECK")) | AE2: =IF(U2="","MISSING",IF(AND(AA2>0,U2/AA2>50),"POSSIBLE_SCALE_ERROR","OK"))
A3: T-2020-P11-0001 | B3: SLE | C3: Chair | D3: Président | E3: Bérubé, Paul-Claude | F3: Board members meeting | G3: Réunion du conseil | H3: 43870 | I3: 43874 | J3: Vancouver, British Columbia, Canada | K3: Vancouver, Colombie-Britannique | P3: 1104.27 | Q3: 189.72 | R3: 841.31 | S3: 461.84 | U3: 2597.14 | X3: casdo-ocena | Y3: Accessibility Standards Canada | Normes d’accessibilité Canada | Z3: 5 | AA3: 2597.14 | AB3: =ROUND(U3-AA3,2) | AC3: FALSE | AD3: =IF(U3="","MISSING_TOTAL",IF(ABS(AB3)<=0.01,"OK","CHECK")) | AE3: =IF(U3="","MISSING",IF(AND(AA3>0,U3/AA3>50),"POSSIBLE_SCALE_ERROR","OK"))
A4: T-2020-P11-0002 | B4: SLE | C4: Vice Chair | D4: vice-présidente | E4: Reid, Mary | F4: Board members meeting | G4: Réunion du conseil | H4: 43870 | I4: 43875 | J4: Vancouver, British Columbia, Canada | K4: Vancouver, Colombie-Britannique | P4: 2511.31 | Q4: 132.48 | R4: 785.65 | S4: 591 | T4: 108.3 | U4: 4128.74 | X4: casdo-ocena | Y4: Accessibility Standards Canada | Normes d’accessibilité Canada | Z4: 6 | AA4: 4128.74 | AB4: =ROUND(U4-AA4,2) | AC4: FALSE | AD4: =IF(U4="","MISSING_TOTAL",IF(ABS(AB4)<=0.01,"OK","CHECK")) | AE4: =IF(U4="","MISSING",IF(AND(AA4>0,U4/AA4>50),"POSSIBLE_SCALE_ERROR","OK"))
A5: T-2020-P11-0003 | B5: SLE | C5: Board Of Directors | D5: Membre du conseil de direction | E5: McLaughlin, Joseph | F5: Board members meeting | G5: Réunion du conseil | H5: 43870 | I5: 43873 | J5: Vancouver, British Columbia, Canada | K5: Vancouver, Colombie-Britannique | Q5: 58.32 | R5: 630.99 | S5: 264.6 | T5: 123 | U5: 1076.91 | X5: casdo-ocena | Y5: Accessibility Standards Canada | Normes d’accessibilité Canada | Z5: 4 | AA5: 1076.91 | AB5: =ROUND(U5-AA5,2) | AC5: FALSE | AD5: =IF(U5="","MISSING_TOTAL",IF(ABS(AB5)<=0.01,"OK","CHECK")) | AE5: =IF(U5="","MISSING",IF(AND(AA5>0,U5/AA5>50),"POSSIBLE_SCALE_ERROR","OK"))
A6: T-2020-P11-0004 | B6: SLE | C6: Board Of Directors | D6: Membre du conseil de direction | E6: Haan, Maureen | F6: Board members meeting | G6: Réunion du conseil | H6: 43870 | I6: 43873 | J6: Vancouver, British Columbia, Canada | K6: Vancouver, Colombie-Britannique | P6: 880.99 | Q6: 192.76 | R6: 630.99 | S6: 332.45 | U6: 2037.19 | X6: casdo-ocena | Y6: Accessibility Standards Canada | Normes d’accessibilité Canada | Z6: 4 | AA6: 2037.19 | AB6: =ROUND(U6-AA6,2) | AC6: FALSE | AD6: =IF(U6="","MISSING_TOTAL",IF(ABS(AB6)<=0.01,"OK","CHECK")) | AE6: =IF(U6="","MISSING",IF(AND(AA6>0,U6/AA6>50),"POSSIBLE_SCALE_ERROR","OK"))
A7: T-2020-P11-0005 | B7: SLE | C7: Board Of Directors | D7: Membre du conseil de direction | E7: Hartin, Penny | F7: Board members meeting | G7: Réunion du conseil | H7: 43870 | I7: 43873 | J7: Vancouver, British Columbia, Canada | K7: Vancouver, Colombie-Britannique | P7: 935.23 | Q7: 117.3 | R7: 630.99 | S7: 353.05 | U7: 2036.57 | X7: casdo-ocena | Y7: Accessibility Standards Canada | Normes d’accessibilité Canada | Z7: 4 | AA7: 2036.57 | AB7: =ROUND(U7-AA7,2) | AC7: FALSE | AD7: =IF(U7="","MISSING_TOTAL",IF(ABS(AB7)<=0.01,"OK","CHECK")) | AE7: =IF(U7="","MISSING",IF(AND(AA7>0,U7/AA7>50),"POSSIBLE_SCALE_ERROR","OK"))
A8: T-2020-P11-0006 | B8: SLE | C8: Board Of Directors | D8: Membre du conseil de direction | E8: Earle, Kory | F8: Board members meeting | G8: Réunion du conseil | H8: 43870 | I8: 43873 | J8: Vancouver, British Columbia, Canada | K8: Vancouver, Colombie-Britannique | P8: 949.11 | R8: 630.99 | S8: 373.4 | U8: 1953.5 | X8: casdo-ocena | Y8: Accessibility Standards Canada | Normes d’accessibilité Canada | Z8: 4 | AA8: 1953.5 | AB8: =ROUND(U8-AA8,2) | AC8: FALSE | AD8: =IF(U8="","MISSING_TOTAL",IF(ABS(AB8)<=0.01,"OK","CHECK")) | AE8: =IF(U8="","MISSING",IF(AND(AA8>0,U8/AA8>50),"POSSIBLE_SCALE_ERROR","OK"))
A9: T-2020-P11-0007 | B9: SLE | C9: Board Of Directors | D9: Membre du conseil de direction | E9: Ringaert, Laurie | F9: Board members meeting | G9: Réunion du conseil | H9: 43870 | I9: 43873 | J9: Vancouver, British Columbia, Canada | K9: Vancouver, Colombie-Britannique | P9: 662.91 | Q9: 128.43 | R9: 630.99 | S9: 332.45 | U9: 1754.78 | X9: casdo-ocena | Y9: Accessibility Standards Canada | Normes d’accessibilité Canada | Z9: 4 | AA9: 1754.78 | AB9: =ROUND(U9-AA9,2) | AC9: FALSE | AD9: =IF(U9="","MISSING_TOTAL",IF(ABS(AB9)<=0.01,"OK","CHECK")) | AE9: =IF(U9="","MISSING",IF(AND(AA9>0,U9/AA9>50),"POSSIBLE_SCALE_ERROR","OK"))
A10: T-2020-P11-0008 | B10: SLE | C10: Board Of Directors | D10: Membre du conseil de direction | E10: Khedr, Rabia | F10: Board members meeting | G10: Réunion du conseil | H10: 43870 | I10: 43873 | J10: Vancouver, British Columbia, Canada | K10: Vancouver, Colombie-Britannique | P10: 935.23 | Q10: 118.3 | R10: 630.99 | S10: 353.05 | U10: 2037.57 | X10: casdo-ocena | Y10: Accessibility Standards Canada | Normes d’accessibilité Canada | Z10: 4 | AA10: 2037.57 | AB10: =ROUND(U10-AA10,2) | AC10: FALSE | AD10: =IF(U10="","MISSING_TOTAL",IF(ABS(AB10)<=0.01,"OK","CHECK")) | AE10: =IF(U10="","MISSING",IF(AND(AA10>0,U10/AA10>50),"POSSIBLE_SCALE_ERROR","OK"))
A11: T-2020-P11-0009 | B11: SLE | C11: Chief Executive Officer | D11: Président-directeur général | E11: Rizcallah, Philip | F11: Board members meeting | G11: Réunion du conseil | H11: 43870 | I11: 43875 | J11: Vancouver, British Columbia, Canada | K11: Vancouver, Colombie-Britannique | P11: 1313.32 | Q11: 342.77 | R11: 970.75 | S11: 591 | T11: 313 | U11: 3530.84 | X11: casdo-ocena | Y11: Accessibility Standards Canada | Normes d’accessibilité Canada | Z11: 6 | AA11: 3530.84 | AB11: =ROUND(U11-AA11,2) | AC11: FALSE | AD11: =IF(U11="","MISSING_TOTAL",IF(ABS(AB11)<=0.01,"OK","CHECK")) | AE11: =IF(U11="","MISSING",IF(AND(AA11>0,U11/AA11>50),"POSSIBLE_SCALE_ERROR","OK"))
A12: T-2020-P1-0001 | B12: SLE | C12: Chair | D12: Président | E12: Bérubé, Paul-Claude | F12: Meeting with Chief Executive Officer of Accessibility Stadards Canada | G12: Réunion avec le Président-directeur général de Normes d’accessibilité Canada | H12: 43880 | I12: 43880 | J12: Montreal, Quebec, Canada | K12: Montréal, Québec, Canada | Q12: 62.06 | R12: 0 | S12: 20.6 | U12: 82.66 | X12: casdo-ocena | Y12: Accessibility Standards Canada | Normes d’accessibilité Canada | Z12: 1 | AA12: 82.66 | AB12: =ROUND(U12-AA12,2) | AC12: FALSE | AD12: =IF(U12="","MISSING_TOTAL",IF(ABS(AB12)<=0.01,"OK","CHECK")) | AE12: =IF(U12="","MISSING",IF(AND(AA12>0,U12/AA12>50),"POSSIBLE_SCALE_ERROR","OK"))
A13: T-2020-P1-0002 | B13: SLE | C13: Chair | D13: Président | E13: Bérubé, Paul-Claude | F13: Meeting with Chief Executive Officer and Staff of of Accessibility Stadards Canada | G13: Réunion avec le Président-directeur général et employés de Normes d’accessibilité Canada | H13: 43885 | I13: 43885 | J13: Ottawa, Ontario, Canada | K13: Ottawa, Ontario, Canada | Q13: 276.06 | R13: 0 | S13: 91.5 | U13: 367.56 | X13: casdo-ocena | Y13: Accessibility Standards Canada | Normes d’accessibilité Canada | Z13: 1 | AA13: 367.56 | AB13: =ROUND(U13-AA13,2) | AC13: FALSE | AD13: =IF(U13="","MISSING_TOTAL",IF(ABS(AB13)<=0.01,"OK","CHECK")) | AE13: =IF(U13="","MISSING",IF(AND(AA13>0,U13/AA13>50),"POSSIBLE_SCALE_ERROR","OK"))
A14: T-2020-P1-0003 | B14: SLE | C14: Chief Executive Officer | D14: Président-directeur général | E14: Rizcallah, Philip | F14: Meetings with various Stakeholders | G14: Réunions avec divers intervenants | H14: 43851 | I14: 43855 | J14: Toronto, Ontario and Halifax, Nova Scotia, Canada | K14: Toronto, Ontario et Halifax, Nouvelle-Écosse, Canada | P14: 1190.86 | Q14: 359.36 | R14: 344.73 | S14: 394.25 | T14: 172.2 | U14: 2461.4 | X14: casdo-ocena | Y14: Accessibility Standards Canada | Normes d’accessibilité Canada | Z14: 5 | AA14: 2461.4 | AB14: =ROUND(U14-AA14,2) | AC14: FALSE | AD14: =IF(U14="","MISSING_TOTAL",IF(ABS(AB14)<=0.01,"OK","CHECK")) | AE14: =IF(U14="","MISSING",IF(AND(AA14>0,U14/AA14>50),"POSSIBLE_SCALE_ERROR","OK"))
A15: T-2020-P2-0001 | B15: SLE | C15: Chief Executive Officer | D15: Président-directeur général | E15: Rizcallah, Philip | F15: To attend Canadian Accessibility Standards Development Organization business meetings | G15: Pour assister des réunions d'affaire de l'Organisation Canadienne d'élaboration de normes d'accessibilité | H15: 43900 | I15: 43900 | J15: Montréal, Quebec, Canada | K15: Montréal, Québec, Canada | P15: 0 | Q15: 339.57 | R15: 0 | S15: 71.15 | T15: 3.2 | U15: 413.92 | X15: casdo-ocena | Y15: Accessibility Standards Canada | Normes d’accessibilité Canada | Z15: 1 | AA15: 413.92 | AB15: =ROUND(U15-AA15,2) | AC15: FALSE | AD15: =IF(U15="","MISSING_TOTAL",IF(ABS(AB15)<=0.01,"OK","CHECK")) | AE15: =IF(U15="","MISSING",IF(AND(AA15>0,U15/AA15>50),"POSSIBLE_SCALE_ERROR","OK"))
A16: T-2020-P2-0002 | B16: SLE | C16: Chief Executive Officer | D16: Président-directeur général | E16: Rizcallah, Philip | F16: To attend meeting with Chair and Chief Operating Officer | G16: Pour assister à une réunion avec le Président et le Chef de l’exploitation | H16: 43880 | I16: 43880 | J16: Montréal, Quebec, Canada | K16: Montréal, Québec, Canada | P16: 0 | Q16: 267.25 | R16: 0 | S16: 20.6 | T16: 0 | U16: 287.85 | X16: casdo-ocena | Y16: Accessibility Standards Canada | Normes d’accessibilité Canada | Z16: 1 | AA16: 287.85 | AB16: =ROUND(U16-AA16,2) | AC16: FALSE | AD16: =IF(U16="","MISSING_TOTAL",IF(ABS(AB16)<=0.01,"OK","CHECK")) | AE16: =IF(U16="","MISSING",IF(AND(AA16>0,U16/AA16>50),"POSSIBLE_SCALE_ERROR","OK"))
A17: T-2020-P2-0003 | B17: SLE | C17: Chief Executive Officer | D17: Président-directeur général | E17: Rizcallah, Philip | F17: To attend meeting with Chair | G17: Pour assister à une réunion avec le Président | H17: 43867 | I17: 43868 | J17: Saint-Jean-sur-Richelieu, Quebec, Canada | K17: Saint-Jean-sur-Richelieu, Québec, Canada | P17: 0 | Q17: 315.28 | R17: 0 | S17: 91.5 | T17: 3.2 | U17: 409.98 | X17: casdo-ocena | Y17: Accessibility Standards Canada | Normes d’accessibilité Canada | Z17: 2 | AA17: 409.98 | AB17: =ROUND(U17-AA17,2) | AC17: FALSE | AD17: =IF(U17="","MISSING_TOTAL",IF(ABS(AB17)<=0.01,"OK","CHECK")) | AE17: =IF(U17="","MISSING",IF(AND(AA17>0,U17/AA17>50),"POSSIBLE_SCALE_ERROR","OK"))
A18: T-2020-P2-0004 | B18: SLE | C18: Chair | D18: Président | E18: Bérubé, Paul-Claude | F18: To attend meeting with Canadian Accessibility Standards Development Organization Chief Executive Officer and Vice-chair | G18: Pour assister à une réunion avec le Directeur général et le Vice-Président du Conseil d'administration de l'Organisation Canadienne d'élaboration de normes d'accessibilité | H18: 43858 | I18: 43858 | J18: Ottawa, Ontario, Canada | K18: Ottawa, Ontario, Canada | P18: 0 | Q18: 563.09 | R18: 0 | S18: 20.6 | T18: 0 | U18: 583.69 | X18: casdo-ocena | Y18: Accessibility Standards Canada | Normes d’accessibilité Canada | Z18: 1 | AA18: 583.69 | AB18: =ROUND(U18-AA18,2) | AC18: FALSE | AD18: =IF(U18="","MISSING_TOTAL",IF(ABS(AB18)<=0.01,"OK","CHECK")) | AE18: =IF(U18="","MISSING",IF(AND(AA18>0,U18/AA18>50),"POSSIBLE_SCALE_ERROR","OK"))
A19: T-2020-P2-0005 | B19: SLE | C19: Chair | D19: Président | E19: Bérubé, Paul-Claude | F19: Physical presence required for Canadian Accessibility Standards Development Organization board members meeting | G19: Participer à la réunion du conseil d'administration de l'Organisation canadienne d'élaboration de normes d'accessibilité | H19: 43851 | I19: 43851 | J19: Ottawa, Ontario, Canada | K19: Ottawa, Ontario, Canada | P19: 0 | Q19: 440.71 | R19: 0 | S19: 20.6 | T19: 0 | U19: 461.31 | X19: casdo-ocena | Y19: Accessibility Standards Canada | Normes d’accessibilité Canada | Z19: 1 | AA19: 461.31 | AB19: =ROUND(U19-AA19,2) | AC19: FALSE | AD19: =IF(U19="","MISSING_TOTAL",IF(ABS(AB19)<=0.01,"OK","CHECK")) | AE19: =IF(U19="","MISSING",IF(AND(AA19>0,U19/AA19>50),"POSSIBLE_SCALE_ERROR","OK"))
A20: T-2020-P2-0006 | B20: SLE | C20: Vice Chair | D20: Vice-Présidente | E20: Reid, Mary | F20: To attend meeting with Canadian Accessibility Standards Development Organization Chief Executive Officer and Chair | G20: Pour assister à une réunion avec le Directeur général du Conseil d'administration et le président de l'Organisation Canadienne d'élaboration de normes d'accessibilité | H20: 43899 | I20: 43900 | J20: Montréal, Quebec, Canada | K20: Montréal, Québec, Canada | P20: 1278.66 | Q20: 32 | R20: 50 | S20: 112.1 | T20: 0 | U20: 1472.76 | X20: casdo-ocena | Y20: Accessibility Standards Canada | Normes d’accessibilité Canada | Z20: 2 | AA20: 1472.76 | AB20: =ROUND(U20-AA20,2) | AC20: FALSE | AD20: =IF(U20="","MISSING_TOTAL",IF(ABS(AB20)<=0.01,"OK","CHECK")) | AE20: =IF(U20="","MISSING",IF(AND(AA20>0,U20/AA20>50),"POSSIBLE_SCALE_ERROR","OK"))
A21: T-2020-P2-0007 | B21: SLE | C21: Vice Chair | D21: Vice-Présidente | E21: Reid, Mary | F21: To attend meeting with Canadian Accessibility Standards Development Organization Chief Executive Officer | G21: Pour assister à une réunion avec le Directeur général du Conseil d'administration de l'Organisation Canadienne d'élaboration de normes d'accessibilité | H21: 43849 | I21: 43850 | J21: Ottawa, Ontario, Canada | K21: Ottawa, Ontario, Canada | P21: 1210.74 | Q21: 70.25 | R21: 269.12 | S21: 197.25 | T21: 0 | U21: 1747.36 | X21: casdo-ocena | Y21: Accessibility Standards Canada | Normes d’accessibilité Canada | Z21: 2 | AA21: 1747.36 | AB21: =ROUND(U21-AA21,2) | AC21: FALSE | AD21: =IF(U21="","MISSING_TOTAL",IF(ABS(AB21)<=0.01,"OK","CHECK")) | AE21: =IF(U21="","MISSING",IF(AND(AA21>0,U21/AA21>50),"POSSIBLE_SCALE_ERROR","OK"))
A22: T-2020-P2-0008 | B22: SLE | C22: Board Of Directors | D22: Membre du conseil d'administration | E22: Adair, William | F22: Physical presence required for Canadian Accessibility Standards Development Organization board members meeting | G22: Participer à la réunion du conseil d'administration de l'Organisation canadienne d'élaboration de normes d'accessibilité | H22: 43870 | I22: 43873 | J22: Vancouver, British Columbia, Canada | K22: Vancouver, Colombie-Britannique, Canada | P22: 894.55 | Q22: 163.15 | R22: 630.99 | S22: 353.05 | T22: 0 | U22: 2041.74 | X22: casdo-ocena | Y22: Accessibility Standards Canada | Normes d’accessibilité Canada | Z22: 4 | AA22: 2041.74 | AB22: =ROUND(U22-AA22,2) | AC22: FALSE | AD22: =IF(U22="","MISSING_TOTAL",IF(ABS(AB22)<=0.01,"OK","CHECK")) | AE22: =IF(U22="","MISSING",IF(AND(AA22>0,U22/AA22>50),"POSSIBLE_SCALE_ERROR","OK"))
A23: T-2022-P5-0001 | B23: SLE | C23: Chief Executive Officer | D23: Président-directeur général | E23: Rizcallah, Philip | F23: Meeting with Government of Quebec | G23: Réunion avec le gouvernement du Québec | H23: 44518 | I23: 44519 | J23: Brossard, Quebec, Canada | K23: Brossard, Québec, Canada | P23: 0 | Q23: 324.3 | R23: 177.31 | S23: 183.55 | T23: 11.6 | U23: 696.76 | X23: casdo-ocena | Y23: Accessibility Standards Canada | Normes d’accessibilité Canada | Z23: 2 | AA23: 696.76 | AB23: =ROUND(U23-AA23,2) | AC23: FALSE | AD23: =IF(U23="","MISSING_TOTAL",IF(ABS(AB23)<=0.01,"OK","CHECK")) | AE23: =IF(U23="","MISSING",IF(AND(AA23>0,U23/AA23>50),"POSSIBLE_SCALE_ERROR","OK"))
A24: T-2022-P5-0002 | B24: SLE | C24: Chief Executive Officer | D24: Président-directeur général | E24: Rizcallah, Philip | F24: Meeting with the Office des personnes handicapées du Québec | G24: Réunion avec l'Office des personnes handicapées du Québec | H24: 44545 | I24: 44546 | J24: Québec, Quebec, Canada | K24: Québec, Québec, Canada | P24: 811.86 | Q24: 235.12 | R24: 154.7 | S24: 226.5 | T24: 0 | U24: 1428.18 | X24: casdo-ocena | Y24: Accessibility Standards Canada | Normes d’accessibilité Canada | Z24: 2 | AA24: 1428.18 | AB24: =ROUND(U24-AA24,2) | AC24: FALSE | AD24: =IF(U24="","MISSING_TOTAL",IF(ABS(AB24)<=0.01,"OK","CHECK")) | AE24: =IF(U24="","MISSING",IF(AND(AA24>0,U24/AA24>50),"POSSIBLE_SCALE_ERROR","OK"))
A25: T-2022-P5-0004 | B25: SLE | C25: Chief Executive Officer | D25: Président-directeur général | E25: Rizcallah, Philip | F25: Stakeholder meetings in Atlantic Canada | G25: Réunions avec parties prenantes | H25: 44604 | I25: 44615 | J25: St. John's, NL | K25: St. John's, TN | P25: 1095.53 | Q25: 304.61 | R25: 553.43 | S25: 884.65 | T25: 253.04 | U25: 3091.26 | X25: casdo-ocena | Y25: Accessibility Standards Canada | Normes d’accessibilité Canada | Z25: 12 | AA25: 3091.26 | AB25: =ROUND(U25-AA25,2) | AC25: FALSE | AD25: =IF(U25="","MISSING_TOTAL",IF(ABS(AB25)<=0.01,"OK","CHECK")) | AE25: =IF(U25="","MISSING",IF(AND(AA25>0,U25/AA25>50),"POSSIBLE_SCALE_ERROR","OK"))
A26: T-2022-P5-0005 | B26: SLE | C26: Chief Executive Officer | D26: Président-directeur général | E26: Rizcallah, Philip | F26: Meeting with Legislative Assembly of New Brunswick | G26: Réunion avec l'Assemblée législative due Nouveau-Brunswick | H26: 44620 | I26: 44621 | J26: Fredericton, NB | K26: Fredericton, NB | P26: 817.28 | Q26: 237.17 | R26: 151.17 | S26: 205.15 | T26: 0 | U26: 1410.77 | X26: casdo-ocena | Y26: Accessibility Standards Canada | Normes d’accessibilité Canada | Z26: 2 | AA26: 1410.77 | AB26: =ROUND(U26-AA26,2) | AC26: FALSE | AD26: =IF(U26="","MISSING_TOTAL",IF(ABS(AB26)<=0.01,"OK","CHECK")) | AE26: =IF(U26="","MISSING",IF(AND(AA26>0,U26/AA26>50),"POSSIBLE_SCALE_ERROR","OK"))
A27: T-2023-P2-0001 | B27: SLE | C27: Chief Executive Officer | D27: Président-directeur général | E27: Rizcallah, Philip | F27: Stakeholder meetings in Toronto | G27: Réunions avec des parties prenantes à Toronto | H27: 44658 | I27: 44660 | J27: Toronto, Ontario, Canada | K27: Toronto, Ontario, Canada | P27: 721.22 | Q27: 193.16 | R27: 491.24 | S27: 292.85 | U27: 1698.47 | X27: casdo-ocena | Y27: Accessibility Standards Canada | Normes d’accessibilité Canada | Z27: 3 | AA27: 1698.47 | AB27: =ROUND(U27-AA27,2) | AC27: FALSE | AD27: =IF(U27="","MISSING_TOTAL",IF(ABS(AB27)<=0.01,"OK","CHECK")) | AE27: =IF(U27="","MISSING",IF(AND(AA27>0,U27/AA27>50),"POSSIBLE_SCALE_ERROR","OK"))
A28: T-2023-P3-0001 | B28: SLE | C28: Chief Executive Officer | D28: Président-directeur général | E28: Rizcallah, Philip | F28: Stakeholder meetings in Halifax | G28: Réunions avec des parties prenantes à Halifax | H28: 44663 | I28: 44668 | J28: Halifax, Nova Scotia, Canada | K28: Halifax, Nouvelle-Ecosse, Canada | P28: 651.37 | Q28: 279.34 | R28: 594.72 | S28: 342.4 | T28: 14.27 | U28: 1882.1 | X28: casdo-ocena | Y28: Accessibility Standards Canada | Normes d’accessibilité Canada | Z28: 6 | AA28: 1882.1 | AB28: =ROUND(U28-AA28,2) | AC28: FALSE | AD28: =IF(U28="","MISSING_TOTAL",IF(ABS(AB28)<=0.01,"OK","CHECK")) | AE28: =IF(U28="","MISSING",IF(AND(AA28>0,U28/AA28>50),"POSSIBLE_SCALE_ERROR","OK"))
A29: T-2023-P3-0002 | B29: SLE | C29: Chief Executive Officer | D29: Président-directeur général | E29: Rizcallah, Philip | F29: Stakeholder meetings in Edmonton | G29: Réunions avec des parties prenantes en Edmonton | H29: 44677 | I29: 44679 | J29: Edmonton, Alberta | K29: Edmonton, Alberta | P29: 1504.7 | Q29: 205.31 | R29: 334.56 | S29: 347.25 | T29: 0 | U29: 2391.82 | X29: casdo-ocena | Y29: Accessibility Standards Canada | Normes d’accessibilité Canada | Z29: 3 | AA29: 2391.82 | AB29: =ROUND(U29-AA29,2) | AC29: FALSE | AD29: =IF(U29="","MISSING_TOTAL",IF(ABS(AB29)<=0.01,"OK","CHECK")) | AE29: =IF(U29="","MISSING",IF(AND(AA29>0,U29/AA29>50),"POSSIBLE_SCALE_ERROR","OK"))
A30: T-2023-P3-0003 | B30: SLE | C30: Chief Executive Officer | D30: Président-directeur général | E30: Rizcallah, Philip | F30: Stakeholder meetings in Victoria and Vancouver | G30: Réunions avec des parties prenantes à Victoria et Vancouver | H30: 44704 | I30: 44707 | J30: Victoria and Vancouver, British Columbia, Canada | K30: Victoria et Vancouver, Colombie-Britannique | P30: 1818.5 | Q30: 691.09 | R30: 900.59 | S30: 463 | T30: 0 | U30: 3873.18 | X30: casdo-ocena | Y30: Accessibility Standards Canada | Normes d’accessibilité Canada | Z30: 4 | AA30: 3873.18 | AB30: =ROUND(U30-AA30,2) | AC30: FALSE | AD30: =IF(U30="","MISSING_TOTAL",IF(ABS(AB30)<=0.01,"OK","CHECK")) | AE30: =IF(U30="","MISSING",IF(AND(AA30>0,U30/AA30>50),"POSSIBLE_SCALE_ERROR","OK"))
A31: T-2023-P4-0001 | B31: SLE | C31: Chief Executive Officer | D31: Président-directeur général | E31: Rizcallah, Philip | F31: Stakeholder meetings in Moncton | G31: Réunions avec des parties prenantes à Moncton | H31: 44733 | I31: 44734 | J31: Moncton, New Brunswick, Canada | K31: Moncton, Nouveau Brunswick, Canada | P31: 986.9 | Q31: 182.9 | R31: 141.55 | S31: 231.5 | T31: 0 | U31: 1542.85 | X31: casdo-ocena | Y31: Accessibility Standards Canada | Normes d’accessibilité Canada | Z31: 2 | AA31: 1542.85 | AB31: =ROUND(U31-AA31,2) | AC31: FALSE | AD31: =IF(U31="","MISSING_TOTAL",IF(ABS(AB31)<=0.01,"OK","CHECK")) | AE31: =IF(U31="","MISSING",IF(AND(AA31>0,U31/AA31>50),"POSSIBLE_SCALE_ERROR","OK"))
A32: T-2023-P4-0002 | B32: SLE | C32: Chief Executive Officer | D32: Président-directeur général | E32: Rizcallah, Philip | F32: Stakeholder meetings in Toronto | G32: Réunions avec des parties prenantes en Toronto | H32: 44735 | I32: 44736 | J32: Toronto, Ontario, Canada | K32: Toronto, Ontario, Canada | P32: 0 | Q32: 665.2 | R32: 404.27 | S32: 231.5 | T32: 23.73 | U32: 1324.7 | X32: casdo-ocena | Y32: Accessibility Standards Canada | Normes d’accessibilité Canada | Z32: 2 | AA32: 1324.7 | AB32: =ROUND(U32-AA32,2) | AC32: FALSE | AD32: =IF(U32="","MISSING_TOTAL",IF(ABS(AB32)<=0.01,"OK","CHECK")) | AE32: =IF(U32="","MISSING",IF(AND(AA32>0,U32/AA32>50),"POSSIBLE_SCALE_ERROR","OK"))
A33: T-2023-P5-0001 | B33: SLE | C33: Chief Executive Officer | D33: Président-directeur général | E33: Rizcallah, Philip | F33: CACP CIPH Annual Meeting | G33: Réunion annuelle CACP CIPH | H33: 44787 | I33: 44790 | J33: Halifax, Nova Scotia, Canada | K33: Halifax, Nouvelle Ecosse, Canada | P33: 698.64 | Q33: 278.92 | R33: 443.4 | S33: 468.95 | T33: 0 | U33: 1889.91 | X33: casdo-ocena | Y33: Accessibility Standards Canada | Normes d’accessibilité Canada | Z33: 4 | AA33: 1889.91 | AB33: =ROUND(U33-AA33,2) | AC33: FALSE | AD33: =IF(U33="","MISSING_TOTAL",IF(ABS(AB33)<=0.01,"OK","CHECK")) | AE33: =IF(U33="","MISSING",IF(AND(AA33>0,U33/AA33>50),"POSSIBLE_SCALE_ERROR","OK"))
A34: T-2023-P5-0002 | B34: SLE | C34: Chief Executive Officer | D34: Président-directeur général | E34: Rizcallah, Philip | F34: Standard and training review | G34: Formation des normes | H34: 44798 | I34: 44800 | J34: Peterborough, Ontario, Canada | K34: Peterborough, Ontario, Canada | P34: 0 | Q34: 336.6 | R34: 369.75 | S34: 270.95 | T34: 0 | U34: 977.3 | X34: casdo-ocena | Y34: Accessibility Standards Canada | Normes d’accessibilité Canada | Z34: 3 | AA34: 977.3 | AB34: =ROUND(U34-AA34,2) | AC34: FALSE | AD34: =IF(U34="","MISSING_TOTAL",IF(ABS(AB34)<=0.01,"OK","CHECK")) | AE34: =IF(U34="","MISSING",IF(AND(AA34>0,U34/AA34>50),"POSSIBLE_SCALE_ERROR","OK"))
A35: T-2023-P5-0003 | B35: SLE | C35: Chair | D35: Président | E35: Bérubé, Paul-Claude | F35: Meeting with CEO | G35: Réunion avec PDG | H35: 44769 | I35: 44769 | J35: Brossard, Quebec, Canada | K35: Brossard, Québec, Canada | P35: 0 | Q35: 41.25 | R35: 0 | S35: 22.15 | T35: 0 | U35: 63.4 | X35: casdo-ocena | Y35: Accessibility Standards Canada | Normes d’accessibilité Canada | Z35: 1 | AA35: 63.4 | AB35: =ROUND(U35-AA35,2) | AC35: FALSE | AD35: =IF(U35="","MISSING_TOTAL",IF(ABS(AB35)<=0.01,"OK","CHECK")) | AE35: =IF(U35="","MISSING",IF(AND(AA35>0,U35/AA35>50),"POSSIBLE_SCALE_ERROR","OK"))
A36: T-2023-P5-0004 | B36: SLE | C36: Chair | D36: Président | E36: Bérubé, Paul-Claude | F36: Meeting with Vie Autonome | G36: Réunion avec Vie Autonome | H36: 44779 | I36: 44779 | J36: Val d'Or, Quebec, Canada | K36: Val d'Or, Québec, Canada | P36: 1633.64 | Q36: 108.7 | R36: 0 | S36: 98.45 | T36: 0 | U36: 1840.79 | X36: casdo-ocena | Y36: Accessibility Standards Canada | Normes d’accessibilité Canada | Z36: 1 | AA36: 1840.79 | AB36: =ROUND(U36-AA36,2) | AC36: FALSE | AD36: =IF(U36="","MISSING_TOTAL",IF(ABS(AB36)<=0.01,"OK","CHECK")) | AE36: =IF(U36="","MISSING",IF(AND(AA36>0,U36/AA36>50),"POSSIBLE_SCALE_ERROR","OK"))
A37: T-2023-P5-0005 | B37: SLE | C37: Chair | D37: Président | E37: Bérubé, Paul-Claude | F37: Meeting with CEO and co-Chair | G37: Réunion avec PDG et co-président | H37: 44752 | I37: 44754 | J37: Gatineau, Quebec, Canada | K37: Gatineau, Québec, Canada | P37: 0 | Q37: 296.04 | R37: 783.04 | S37: 259.4 | T37: 0 | U37: 1338.48 | X37: casdo-ocena | Y37: Accessibility Standards Canada | Normes d’accessibilité Canada | Z37: 3 | AA37: 1338.48 | AB37: =ROUND(U37-AA37,2) | AC37: FALSE | AD37: =IF(U37="","MISSING_TOTAL",IF(ABS(AB37)<=0.01,"OK","CHECK")) | AE37: =IF(U37="","MISSING",IF(AND(AA37>0,U37/AA37>50),"POSSIBLE_SCALE_ERROR","OK"))
A38: T-2023-P5-0006 | B38: SLE | C38: Board Member | D38: Membre du conseil d'administration | E38: McLaughlin, Joseph | F38: Stakeholder meeting | G38: Réunion des parties prenantes | H38: 44706 | I38: 44706 | J38: Vancouver, British Columbia, Canada | K38: Vancouver, Colombie Britannique, Canada | P38: 0 | Q38: 49.68 | R38: 0 | S38: 0 | U38: 49.68 | X38: casdo-ocena | Y38: Accessibility Standards Canada | Normes d’accessibilité Canada | Z38: 1 | AA38: 49.68 | AB38: =ROUND(U38-AA38,2) | AC38: FALSE | AD38: =IF(U38="","MISSING_TOTAL",IF(ABS(AB38)<=0.01,"OK","CHECK")) | AE38: =IF(U38="","MISSING",IF(AND(AA38>0,U38/AA38>50),"POSSIBLE_SCALE_ERROR","OK"))
A39: T-2023-P6-0001 | B39: SLE | C39: Vice Chair | D39: Vice président | E39: Reid, Mary | F39: Meeting with CEO and Chair | G39: Réunion avec PDG et Président | H39: 44745 | I39: 44755 | J39: Gatineau, Quebec, Canada | K39: Gatineau, Québec, Canada | P39: 780.54 | Q39: 50 | R39: 371.32 | S39: 270.7 | T39: 0 | U39: 1472.56 | X39: casdo-ocena | Y39: Accessibility Standards Canada | Normes d’accessibilité Canada | Z39: 11 | AA39: 1472.56 | AB39: =ROUND(U39-AA39,2) | AC39: FALSE | AD39: =IF(U39="","MISSING_TOTAL",IF(ABS(AB39)<=0.01,"OK","CHECK")) | AE39: =IF(U39="","MISSING",IF(AND(AA39>0,U39/AA39>50),"POSSIBLE_SCALE_ERROR","OK"))
A40: T-2023-P7-0001 | B40: SLE | C40: Chief Executive Officer | D40: Président-directeur général | E40: Rizcallah, Philip | F40: International conference on Universal Design | G40: Conférence internationale sur la conception universelle | H40: 44805 | I40: 44814 | J40: Venice, Italy | K40: Venise, Italie | P40: 12175.56 | Q40: 592.46 | R40: 996.34 | S40: 731.55 | T40: 0 | U40: 14495.91 | X40: casdo-ocena | Y40: Accessibility Standards Canada | Normes d’accessibilité Canada | Z40: 10 | AA40: 14495.91 | AB40: =ROUND(U40-AA40,2) | AC40: FALSE | AD40: =IF(U40="","MISSING_TOTAL",IF(ABS(AB40)<=0.01,"OK","CHECK")) | AE40: =IF(U40="","MISSING",IF(AND(AA40>0,U40/AA40>50),"POSSIBLE_SCALE_ERROR","OK"))
...

Sheet Data_Quality_Summary
A1: Data Quality Metric | B1: COUNT
A2: Total Records | B2: =COUNTA(Cleaned_Data!A2:A152901)
A3: Missing Airfare | B3: =COUNTBLANK(Cleaned_Data!P2:P152901)
A4: Missing Other Transport | B4: =COUNTBLANK(Cleaned_Data!Q2:Q152901)
A5: Missing Lodging | B5: =COUNTBLANK(Cleaned_Data!R2:R152901)
A6: Missing Meals | B6: =COUNTBLANK(Cleaned_Data!S2:S152901)
A7: Missing Other Expenses | B7: =COUNTBLANK(Cleaned_Data!T2:T152901)
A8: Missing Total | B8: =COUNTBLANK(Cleaned_Data!U2:U152901)
A9: Duplicate Records | B9: =COUNTIF(Cleaned_Data!AC2:AC152901,TRUE)
A10: Possible Scale Errors | B10: =COUNTIF(Cleaned_Data!AE2:AE152901,"POSSIBLE_SCALE_ERROR")

Sheet Analysis
A1: KPI | B1: Value | D1: Year | E1: Total Expense | G1: Department | H1: Total Expense | J1: Destination | K1: Total Expense | M1: Expense Category | N1: Total Expense
A2: Total Travel Records | B2: =COUNTA(Cleaned_Data!A2:A152901) | D2: =IFERROR(__xludf.DUMMYFUNCTION("QUERY({ARRAYFORMULA(YEAR(Cleaned_Data!H2:H22699)),Cleaned_Data!U2:U22699},""select Col1, sum(Col2) where Col1 is not null and Col2 is not null group by Col1 order by Col1"",0)"),"") | E2: =IFERROR(__xludf.DUMMYFUNCTION("""COMPUTED_VALUE"""),"sum ") | G2: =IFERROR(__xludf.DUMMYFUNCTION("QUERY({Cleaned_Data!Y2:Y22699,Cleaned_Data!U2:U22699},""select Col1, sum(Col2) where Col1 is not null and Col2 is not null group by Col1 order by sum(Col2) desc label Col1 'Department', sum(Col2) 'Total Expense'"",0)"),"Department") | H2: =IFERROR(__xludf.DUMMYFUNCTION("""COMPUTED_VALUE"""),"Total Expense") | J2: =IFERROR(__xludf.DUMMYFUNCTION("QUERY({Cleaned_Data!J2:J22699,Cleaned_Data!U2:U22699},""select Col1, sum(Col2) where Col1 is not null and Col2 is not null group by Col1 order by sum(Col2) desc label Col1 'Destination', sum(Col2) 'Total Expense'"",0)"),"Destination") | K2: =IFERROR(__xludf.DUMMYFUNCTION("""COMPUTED_VALUE"""),"Total Expense") | M2: {="Airfare"} | N2: Airfare
A3: Total Travel Expense | B3: =SUM(Cleaned_Data!U2:U152901) | D3: =IFERROR(__xludf.DUMMYFUNCTION("""COMPUTED_VALUE"""),1999) | E3: =IFERROR(__xludf.DUMMYFUNCTION("""COMPUTED_VALUE"""),0) | G3: =IFERROR(__xludf.DUMMYFUNCTION("""COMPUTED_VALUE"""),"Global Affairs Canada | Affaires mondiales Canada") | H3: =IFERROR(__xludf.DUMMYFUNCTION("""COMPUTED_VALUE"""),63848705.3699997) | J3: =IFERROR(__xludf.DUMMYFUNCTION("""COMPUTED_VALUE"""),"Toronto, Ontario, Canada") | K3: =IFERROR(__xludf.DUMMYFUNCTION("""COMPUTED_VALUE"""),13178794.05) | M3: Airfare | N3: Airfare
A4: Average Travel Expense | B4: =AVERAGE(Cleaned_Data!U2:U22699) | D4: =IFERROR(__xludf.DUMMYFUNCTION("""COMPUTED_VALUE"""),2003) | E4: =IFERROR(__xludf.DUMMYFUNCTION("""COMPUTED_VALUE"""),67137.58) | G4: =IFERROR(__xludf.DUMMYFUNCTION("""COMPUTED_VALUE"""),"Employment and Social Development Canada | Emploi et Développement social Canada") | H4: =IFERROR(__xludf.DUMMYFUNCTION("""COMPUTED_VALUE"""),23424267.77) | J4: =IFERROR(__xludf.DUMMYFUNCTION("""COMPUTED_VALUE"""),"Ottawa, Ontario, Canada") | K4: =IFERROR(__xludf.DUMMYFUNCTION("""COMPUTED_VALUE"""),13173293.9) | M4: Airfare | N4: Airfare
A5: Maximum Travel Expense | B5: =MAX(Cleaned_Data!U2:U22699) | D5: =IFERROR(__xludf.DUMMYFUNCTION("""COMPUTED_VALUE"""),2004) | E5: =IFERROR(__xludf.DUMMYFUNCTION("""COMPUTED_VALUE"""),4540905.82) | G5: =IFERROR(__xludf.DUMMYFUNCTION("""COMPUTED_VALUE"""),"National Defence | Défense nationale") | H5: =IFERROR(__xludf.DUMMYFUNCTION("""COMPUTED_VALUE"""),22382126.4799999) | J5: =IFERROR(__xludf.DUMMYFUNCTION("""COMPUTED_VALUE"""),"Vancouver, British Columbia, Canada") | K5: =IFERROR(__xludf.DUMMYFUNCTION("""COMPUTED_VALUE"""),6812316.72) | M5: Airfare | N5: Airfare
A6: Minimum Travel Expense | B6: =MIN(Cleaned_Data!U2:U22699) | D6: =IFERROR(__xludf.DUMMYFUNCTION("""COMPUTED_VALUE"""),2005) | E6: =IFERROR(__xludf.DUMMYFUNCTION("""COMPUTED_VALUE"""),5272765.43) | G6: =IFERROR(__xludf.DUMMYFUNCTION("""COMPUTED_VALUE"""),"Department of Finance Canada | Ministère des Finances Canada") | H6: =IFERROR(__xludf.DUMMYFUNCTION("""COMPUTED_VALUE"""),18165295.0799999) | J6: =IFERROR(__xludf.DUMMYFUNCTION("""COMPUTED_VALUE"""),"Paris, France") | K6: =IFERROR(__xludf.DUMMYFUNCTION("""COMPUTED_VALUE"""),6136294.43) | M6: Airfare | N6: Airfare
A7: Total Airfare | B7: =SUM(Cleaned_Data!P2:P22699) | D7: =IFERROR(__xludf.DUMMYFUNCTION("""COMPUTED_VALUE"""),2006) | E7: =IFERROR(__xludf.DUMMYFUNCTION("""COMPUTED_VALUE"""),4938243.25000001) | G7: =IFERROR(__xludf.DUMMYFUNCTION("""COMPUTED_VALUE"""),"Innovation, Science and Economic Development Canada | Innovation, Sciences et Développement économique Canada") | H7: =IFERROR(__xludf.DUMMYFUNCTION("""COMPUTED_VALUE"""),12558238.84) | J7: =IFERROR(__xludf.DUMMYFUNCTION("""COMPUTED_VALUE"""),"Montreal, Quebec, Canada") | K7: =IFERROR(__xludf.DUMMYFUNCTION("""COMPUTED_VALUE"""),5001970.51000001)
A8: Total Other Transport | B8: =SUM(Cleaned_Data!Q2:Q22699) | D8: =IFERROR(__xludf.DUMMYFUNCTION("""COMPUTED_VALUE"""),2007) | E8: =IFERROR(__xludf.DUMMYFUNCTION("""COMPUTED_VALUE"""),6196268.95) | G8: =IFERROR(__xludf.DUMMYFUNCTION("""COMPUTED_VALUE"""),"Privy Council Office | Bureau du Conseil privé") | H8: =IFERROR(__xludf.DUMMYFUNCTION("""COMPUTED_VALUE"""),10296318.65) | J8: =IFERROR(__xludf.DUMMYFUNCTION("""COMPUTED_VALUE"""),"Ottawa, Ontario") | K8: =IFERROR(__xludf.DUMMYFUNCTION("""COMPUTED_VALUE"""),4531891.71)
A9: Total Lodging | B9: =SUM(Cleaned_Data!R2:R22699) | D9: =IFERROR(__xludf.DUMMYFUNCTION("""COMPUTED_VALUE"""),2008) | E9: =IFERROR(__xludf.DUMMYFUNCTION("""COMPUTED_VALUE"""),6073208.93) | G9: =IFERROR(__xludf.DUMMYFUNCTION("""COMPUTED_VALUE"""),"Natural Resources Canada | Ressources naturelles Canada") | H9: =IFERROR(__xludf.DUMMYFUNCTION("""COMPUTED_VALUE"""),8618916.91) | J9: =IFERROR(__xludf.DUMMYFUNCTION("""COMPUTED_VALUE"""),"Ottawa, ON") | K9: =IFERROR(__xludf.DUMMYFUNCTION("""COMPUTED_VALUE"""),4267074.72999999)
A10: Total Meals | B10: =SUM(Cleaned_Data!S2:S22699) | D10: =IFERROR(__xludf.DUMMYFUNCTION("""COMPUTED_VALUE"""),2009) | E10: =IFERROR(__xludf.DUMMYFUNCTION("""COMPUTED_VALUE"""),7694189.17) | G10: =IFERROR(__xludf.DUMMYFUNCTION("""COMPUTED_VALUE"""),"Canada Revenue Agency | Agence du revenu du Canada") | H10: =IFERROR(__xludf.DUMMYFUNCTION("""COMPUTED_VALUE"""),7277975.67) | J10: =IFERROR(__xludf.DUMMYFUNCTION("""COMPUTED_VALUE"""),"Toronto, ON") | K10: =IFERROR(__xludf.DUMMYFUNCTION("""COMPUTED_VALUE"""),3927901.39999999)
A11: Total Other Expenses | B11: =SUM(Cleaned_Data!T2:T22699) | D11: =IFERROR(__xludf.DUMMYFUNCTION("""COMPUTED_VALUE"""),2010) | E11: =IFERROR(__xludf.DUMMYFUNCTION("""COMPUTED_VALUE"""),7828816.55) | G11: =IFERROR(__xludf.DUMMYFUNCTION("""COMPUTED_VALUE"""),"Canadian Heritage | Patrimoine canadien") | H11: =IFERROR(__xludf.DUMMYFUNCTION("""COMPUTED_VALUE"""),7084876.46) | J11: =IFERROR(__xludf.DUMMYFUNCTION("""COMPUTED_VALUE"""),"Calgary, Alberta, Canada") | K11: =IFERROR(__xludf.DUMMYFUNCTION("""COMPUTED_VALUE"""),3506254.52999999)
A12: Total Travel Days | B12: =SUM(Cleaned_Data!Z2:Z22699) | D12: =IFERROR(__xludf.DUMMYFUNCTION("""COMPUTED_VALUE"""),2011) | E12: =IFERROR(__xludf.DUMMYFUNCTION("""COMPUTED_VALUE"""),8151691.18) | G12: =IFERROR(__xludf.DUMMYFUNCTION("""COMPUTED_VALUE"""),"Transport Canada | Transports Canada") | H12: =IFERROR(__xludf.DUMMYFUNCTION("""COMPUTED_VALUE"""),6703932.18) | J12: =IFERROR(__xludf.DUMMYFUNCTION("""COMPUTED_VALUE"""),"Halifax, Nova Scotia, Canada") | K12: =IFERROR(__xludf.DUMMYFUNCTION("""COMPUTED_VALUE"""),3328456.59)
A13: Average Travel Days | B13: =AVERAGE(Cleaned_Data!Z2:Z22699) | D13: =IFERROR(__xludf.DUMMYFUNCTION("""COMPUTED_VALUE"""),2012) | E13: =IFERROR(__xludf.DUMMYFUNCTION("""COMPUTED_VALUE"""),8875390.37000001) | G13: =IFERROR(__xludf.DUMMYFUNCTION("""COMPUTED_VALUE"""),"Veterans Affairs Canada | Anciens Combattants Canada") | H13: =IFERROR(__xludf.DUMMYFUNCTION("""COMPUTED_VALUE"""),6294153.4) | J13: =IFERROR(__xludf.DUMMYFUNCTION("""COMPUTED_VALUE"""),"London, United Kingdom") | K13: =IFERROR(__xludf.DUMMYFUNCTION("""COMPUTED_VALUE"""),3265268.56)
A14: Maximum Travel Days | B14: =MAX(Cleaned_Data!Z2:Z22699) | D14: =IFERROR(__xludf.DUMMYFUNCTION("""COMPUTED_VALUE"""),2013) | E14: =IFERROR(__xludf.DUMMYFUNCTION("""COMPUTED_VALUE"""),8552043.13999999) | G14: =IFERROR(__xludf.DUMMYFUNCTION("""COMPUTED_VALUE"""),"Environment and Climate Change Canada | Environnement et Changement climatique Canada") | H14: =IFERROR(__xludf.DUMMYFUNCTION("""COMPUTED_VALUE"""),5863791.55000001) | J14: =IFERROR(__xludf.DUMMYFUNCTION("""COMPUTED_VALUE"""),"Geneva, Switzerland") | K14: =IFERROR(__xludf.DUMMYFUNCTION("""COMPUTED_VALUE"""),3115396.61)
A15: Records with Missing Total | B15: =COUNTIFS(Cleaned_Data!A2:A22699,"<>",Cleaned_Data!U2:U22699,"") | D15: =IFERROR(__xludf.DUMMYFUNCTION("""COMPUTED_VALUE"""),2014) | E15: =IFERROR(__xludf.DUMMYFUNCTION("""COMPUTED_VALUE"""),9872197.84999997) | G15: =IFERROR(__xludf.DUMMYFUNCTION("""COMPUTED_VALUE"""),"Immigration, Refugees and Citizenship Canada | Immigration, Réfugiés et Citoyenneté Canada") | H15: =IFERROR(__xludf.DUMMYFUNCTION("""COMPUTED_VALUE"""),5643369.53999999) | J15: =IFERROR(__xludf.DUMMYFUNCTION("""COMPUTED_VALUE"""),"Tokyo, Japan") | K15: =IFERROR(__xludf.DUMMYFUNCTION("""COMPUTED_VALUE"""),2898174.22999999)
A16: Records with Missing Airfare | B16: =COUNTIFS(Cleaned_Data!A2:A22699,"<>",Cleaned_Data!P2:P22699,"") | D16: =IFERROR(__xludf.DUMMYFUNCTION("""COMPUTED_VALUE"""),2015) | E16: =IFERROR(__xludf.DUMMYFUNCTION("""COMPUTED_VALUE"""),9543954.88999999) | G16: =IFERROR(__xludf.DUMMYFUNCTION("""COMPUTED_VALUE"""),"National Research Council Canada | Conseil national de recherches Canada") | H16: =IFERROR(__xludf.DUMMYFUNCTION("""COMPUTED_VALUE"""),5333036.58) | J16: =IFERROR(__xludf.DUMMYFUNCTION("""COMPUTED_VALUE"""),"Toronto, Ontario") | K16: =IFERROR(__xludf.DUMMYFUNCTION("""COMPUTED_VALUE"""),2777159.74)
A17: Records with Missing Lodging | B17: =COUNTIFS(Cleaned_Data!A2:A22699,"<>",Cleaned_Data!R2:R22699,"") | D17: =IFERROR(__xludf.DUMMYFUNCTION("""COMPUTED_VALUE"""),2016) | E17: =IFERROR(__xludf.DUMMYFUNCTION("""COMPUTED_VALUE"""),13455707.96) | G17: =IFERROR(__xludf.DUMMYFUNCTION("""COMPUTED_VALUE"""),"Parks Canada | Parcs Canada") | H17: =IFERROR(__xludf.DUMMYFUNCTION("""COMPUTED_VALUE"""),5234603.90999999) | J17: =IFERROR(__xludf.DUMMYFUNCTION("""COMPUTED_VALUE"""),"Winnipeg, Manitoba, Canada") | K17: =IFERROR(__xludf.DUMMYFUNCTION("""COMPUTED_VALUE"""),2652310.01)
A18: Records with Missing Meals | B18: =COUNTIFS(Cleaned_Data!A2:A22699,"<>",Cleaned_Data!S2:S22699,"") | D18: =IFERROR(__xludf.DUMMYFUNCTION("""COMPUTED_VALUE"""),2017) | E18: =IFERROR(__xludf.DUMMYFUNCTION("""COMPUTED_VALUE"""),20512941.39) | G18: =IFERROR(__xludf.DUMMYFUNCTION("""COMPUTED_VALUE"""),"Fisheries and Oceans Canada | Pêches et Océans Canada") | H18: =IFERROR(__xludf.DUMMYFUNCTION("""COMPUTED_VALUE"""),5036499.06999999) | J18: =IFERROR(__xludf.DUMMYFUNCTION("""COMPUTED_VALUE"""),"Brussels, Belgium") | K18: =IFERROR(__xludf.DUMMYFUNCTION("""COMPUTED_VALUE"""),2632637.81999999)
A19: Records with Missing Other Expenses | B19: =COUNTIFS(Cleaned_Data!A2:A22699,"<>",Cleaned_Data!T2:T22699,"") | D19: =IFERROR(__xludf.DUMMYFUNCTION("""COMPUTED_VALUE"""),2018) | E19: =IFERROR(__xludf.DUMMYFUNCTION("""COMPUTED_VALUE"""),24835584.7699999) | G19: =IFERROR(__xludf.DUMMYFUNCTION("""COMPUTED_VALUE"""),"Farm Credit Canada | Financement agricole Canada") | H19: =IFERROR(__xludf.DUMMYFUNCTION("""COMPUTED_VALUE"""),5005716.26999999) | J19: =IFERROR(__xludf.DUMMYFUNCTION("""COMPUTED_VALUE"""),"Regina, Saskatchewan, Canada") | K19: =IFERROR(__xludf.DUMMYFUNCTION("""COMPUTED_VALUE"""),2285521.33)
A20: Duplicate Records | B20: =COUNTIF(Cleaned_Data!AC2:AC22699,TRUE) | D20: =IFERROR(__xludf.DUMMYFUNCTION("""COMPUTED_VALUE"""),2019) | E20: =IFERROR(__xludf.DUMMYFUNCTION("""COMPUTED_VALUE"""),23693199.4099999) | G20: =IFERROR(__xludf.DUMMYFUNCTION("""COMPUTED_VALUE"""),"Agriculture and Agri-Food Canada | Agriculture et Agroalimentaire Canada") | H20: =IFERROR(__xludf.DUMMYFUNCTION("""COMPUTED_VALUE"""),4470756.54) | J20: =IFERROR(__xludf.DUMMYFUNCTION("""COMPUTED_VALUE"""),"Vancouver, BC") | K20: =IFERROR(__xludf.DUMMYFUNCTION("""COMPUTED_VALUE"""),2179139.43)
